<mujoco model="cheetah">
  <compiler angle="radian" meshdir="meshes/" inertiafromgeom="false"/>

  <asset>
    <mesh name="fl_hip" file="fl_hip.STL"/>
    <mesh name="fl_knee" file="fl_knee.STL"/>
  </asset>

  <worldbody>
    <body name="fl_hip">
      <inertial pos="0 -0.0083713 -0.088755" quat="0.997892 0.0648985 0 0" mass="0.42319" diaginertia="0.0034493 0.00319477 0.000746558"/>
      <joint name="fl_hip_joint" pos="0 0 0" axis="0 1 0"/>
      <geom type="mesh" mesh="fl_hip"/>
      <geom type="capsule" size="0.045" fromto="0 0.0225 0 0 0.0225 -0.21" group="0" contype="1" conaffinity="1"  rgba="0.85 0.65 0.25 0.5"/>
      <body name="fl_knee" pos="0 0 -0.21" quat="0.965926 0 0.25882 0">
        <inertial pos="0.13698 0 0" quat="0.5 0.5 0.5 0.5" mass="0.19172" diaginertia="0.0020898 0.0020349 8.8217e-05"/>
        <joint name="fl_knee_joint" pos="0 0 0" axis="0 1 0"/>
        <geom type="mesh" mesh="fl_knee"/>
        <geom type="capsule" size="0.035" fromto="0.08 0.0225 0 0.29 0.0225 0" group="0" contype="1" conaffinity="1"  rgba="0.85 0.65 0.25 0.5"/>
        <body name="fl_foot" pos="0.29 0.0225 0">
          <inertial pos="0 0 0" mass="0.001" diaginertia="0.001 0.001 0.001"/>
          <geom group="1" type="sphere" size="0.035" solimp="0.015 1 0.031" friction="0.8 0.02 0.01" rgba="0 0 0 0.5"/>
          <site name="fl_foot"/>
        </body>
      </body>
    </body>
  </worldbody>

  <actuator>
    <general name="fl_hip_act" joint="fl_hip_joint"/>
    <general name="fl_knee_act" joint="fl_knee_joint"/>
  </actuator>

  <sensor>
    <jointpos joint="fl_hip_joint" name="fl_hip_pos"/>
    <jointpos joint="fl_knee_joint" name="fl_knee_pos"/>
    <jointvel joint="fl_hip_joint" name="fl_hip_vel"/>
    <jointvel joint="fl_knee_joint" name="fl_knee_vel"/>
  </sensor>
</mujoco>
