<mujoco model="cheetah">
  <compiler angle="radian" meshdir="meshes/"/>

  <statistic center="0 0 0.1" extent="0.8"/>

  <visual>
    <headlight diffuse="0.6 0.6 0.6" ambient="0.3 0.3 0.3" specular="0 0 0"/>
    <rgba haze="0.15 0.25 0.35 1"/>
    <global azimuth="120" elevation="-20"/>
  </visual>

  <default>
    <geom group="2" contype="0" conaffinity="0" density="0" type="mesh"/>
    <default class="cheetah/collision">
      <geom group="0" contype="1" conaffinity="1" density="0" material="collision"/>
    </default>
    <default class="cheetah/foot">
      <geom group="1" type="sphere" density="0" size="0.035" solimp="0.015 1 0.031" friction="0.8 0.02 0.01" material="contact"/>
    </default>
    <general forcerange="-18 18" biastype="affine" gainprm="50 0 0" biasprm="0 -50 -0.5"/>
    <joint damping="0.024" armature="0.011" range="-0.78 0.78"/>
  </default>

  <asset>
    <mesh name="base" file="base.STL"/>
    <mesh name="fl_hip" file="fl_hip.STL"/>
    <mesh name="fl_knee" file="fl_knee.STL"/>
    <mesh name="fr_hip" file="fr_hip.STL"/>
    <mesh name="fr_knee" file="fr_knee.STL"/>
    <mesh name="spine" file="spine.STL"/>
    <mesh name="bl_hip" file="bl_hip.STL"/>
    <mesh name="bl_knee" file="bl_knee.STL"/>
    <mesh name="br_hip" file="br_hip.STL"/>
    <mesh name="br_knee" file="br_knee.STL"/>
    <texture type="skybox" builtin="gradient" rgb1="0.3 0.5 0.7" rgb2="0 0 0" width="512" height="3072"/>
    <texture type="2d" name="groundplane" builtin="checker" mark="edge" rgb1="0.2 0.3 0.4" rgb2="0.1 0.2 0.3"
      markrgb="0.8 0.8 0.8" width="300" height="300"/>
    <material name="groundplane" texture="groundplane" texuniform="true" texrepeat="5 5" reflectance="0.2"/>
    <material name="collision" rgba="0.85 0.65 0.25 0.5"/>
    <material name="contact" rgba="0 0 0 0.5"/>
  </asset>

  <worldbody>
    <light pos="0 0 1.5" dir="0 0 -1" directional="true"/>
    <camera name="default" pos="0.846 -1.465 0.916" xyaxes="0.866 0.500 0.000 -0.171 0.296 0.940"/>
    <geom name="floor" size="0 0 0.05" type="plane" material="groundplane" group="0" contype="1" conaffinity="1"/>
    <body name="base">
      <inertial pos="0.36059 -3.5411e-08 2.6263e-08" quat="0.500003 0.500003 0.499997 0.499997" mass="4" diaginertia="0.086585 0.086267 0.031067"/>
      <joint name="floating_base_joint" type="free" limited="false" actuatorfrclimited="false"/>
      <geom type="mesh" mesh="base"/>
      <geom type="capsule" size="0.14" fromto="0.215 0 0 0.515 0 0" class="cheetah/collision"/>
      <site name="imu_frame" pos="0.485 0 0"/>
      <body name="fl_hip" pos="0.485 0.1775 0">
        <inertial pos="0 -0.0083713 -0.088755" quat="0.997892 0.0648985 0 0" mass="0.42319" diaginertia="0.0034493 0.00319477 0.000746558"/>
        <joint name="fl_hip_joint" pos="0 0 0" axis="0 1 0"/>
        <geom type="mesh" mesh="fl_hip"/>
        <geom type="capsule" size="0.045" fromto="0 0.0225 0 0 0.0225 -0.21" class="cheetah/collision"/>
        <body name="fl_knee" pos="0 0 -0.21" quat="0.965926 0 0.25882 0">
          <inertial pos="0.13698 0 0" quat="0.5 0.5 0.5 0.5" mass="0.19172" diaginertia="0.0020898 0.0020349 8.8217e-05"/>
          <joint name="fl_knee_joint" pos="0 0 0" axis="0 1 0"/>
          <geom type="mesh" mesh="fl_knee"/>
          <geom type="capsule" size="0.035" fromto="0.08 0.0225 0 0.29 0.0225 0" class="cheetah/collision"/>
          <body name="fl_foot" pos="0.29 0.0225 0">
            <inertial pos="0 0 0" mass="0.001" diaginertia="0.001 0.001 0.001"/>
            <geom class="cheetah/foot"/>
            <site name="fl_foot"/>
          </body>
        </body>
      </body>
      <body name="fr_hip" pos="0.485 -0.1775 0">
        <inertial pos="0 0.0083713 -0.088755" quat="0.997892 -0.0648985 0 0" mass="0.42319" diaginertia="0.0034493 0.00319477 0.000746558"/>
        <joint name="fr_hip_joint" pos="0 0 0" axis="0 1 0"/>
        <geom type="mesh" mesh="fr_hip"/>
        <geom type="capsule" size="0.045" fromto="0 -0.0225 0 0 -0.0225 -0.21" class="cheetah/collision"/>
        <body name="fr_knee" pos="0 0 -0.21" quat="0.965926 0 0.25882 0">
          <inertial pos="0.13698 0 0" quat="0.5 0.5 0.5 0.5" mass="0.19172" diaginertia="0.0020898 0.0020349 8.8217e-05"/>
          <joint name="fr_knee_joint" pos="0 0 0" axis="0 1 0"/>
          <geom type="mesh" mesh="fr_knee"/>
          <geom type="capsule" size="0.035" fromto="0.08 -0.0225 0 0.29 -0.0225 0" class="cheetah/collision"/>
          <body name="fr_foot" pos="0.29 -0.0225 0">
            <inertial pos="0 0 0" mass="0.001" diaginertia="0.001 0.001 0.001"/>
            <geom class="cheetah/foot"/>
            <site name="fr_foot"/>
          </body>
        </body>
      </body>
      <body name="spine" quat="0.965926 0 0.25882 0">
        <inertial pos="-0.21386 2.4147e-07 -3.6136e-08" quat="0.500007 0.499998 0.5 0.499994" mass="2.818" diaginertia="0.019596 0.019319 0.0104"/>
        <joint name="spine_joint" pos="0 0 0" axis="0 1 0"/>
        <geom type="mesh" mesh="spine"/>
        <geom type="capsule" size="0.0975" fromto="-0.1725 0 0 -0.270 0 0" class="cheetah/collision"/>
        <body name="bl_hip" pos="-0.28023 0.1375 0" quat="0.999048 0 0.0436192 0">
          <inertial pos="-1.5467e-06 -0.0036898 -0.092943" quat="0.999589 0.0286807 1.42074e-05 -8.99596e-06" mass="0.40409" diaginertia="0.0030903 0.00299916 0.000578271"/>
          <joint name="bl_hip_joint" pos="0 0 0" axis="0 1 0"/>
          <geom type="mesh" mesh="bl_hip"/>
          <geom type="capsule" size="0.045" fromto="0 0.0225 0 0 0.0225 -0.21" class="cheetah/collision"/>
          <body name="bl_knee" pos="0 0 -0.21" quat="0.965926 0 -0.25882 0">
            <inertial pos="-0.136981 0 0" quat="0.5 0.5 0.5 0.5" mass="0.191716" diaginertia="0.00208985 0.00203485 8.82166e-05"/>
            <joint name="bl_knee_joint" pos="0 0 0" axis="0 1 0"/>
            <geom type="mesh" mesh="bl_knee"/>
            <geom type="capsule" size="0.035" fromto="-0.08 0.0225 0 -0.29 0.0225 0" class="cheetah/collision"/>
            <body name="bl_foot" pos="-0.29 0.0225 0">
              <inertial pos="0 0 0" mass="0.001" diaginertia="0.001 0.001 0.001"/>
              <geom class="cheetah/foot"/>
              <site name="bl_foot"/>
            </body>
          </body>
        </body>
        <body name="br_hip" pos="-0.28023 -0.1375 0" quat="0.999048 0 0.0436192 0">
          <inertial pos="0 0.00368968 -0.092947" quat="0.999589 -0.0286799 0 0" mass="0.404108" diaginertia="0.00309049 0.00299939 0.00057831"/>
          <joint name="br_hip_joint" pos="0 0 0" axis="0 1 0"/>
          <geom type="mesh" mesh="br_hip"/>
          <geom type="capsule" size="0.045" fromto="0 -0.0225 0 0 -0.0225 -0.21" class="cheetah/collision"/>
          <body name="br_knee" pos="0 0 -0.21" quat="0.965926 0 -0.25882 0">
            <inertial pos="-0.136981 0 0" quat="0.5 0.5 0.5 0.5" mass="0.191716" diaginertia="0.00208985 0.00203485 8.82166e-05"/>
            <joint name="br_knee_joint" pos="0 0 0" axis="0 1 0"/>
            <geom type="mesh" mesh="br_knee"/>
            <geom type="capsule" size="0.035" fromto="-0.08 -0.0225 0 -0.29 -0.0225 0" class="cheetah/collision"/>
            <body name="br_foot" pos="-0.29 -0.0225 0">
              <inertial pos="0 0 0" mass="0.001" diaginertia="0.001 0.001 0.001"/>
              <geom class="cheetah/foot"/>
              <site name="br_foot"/>
            </body>
          </body>
        </body>
      </body>
    </body>
  </worldbody>

  <actuator>
    <general name="fl_hip_act" joint="fl_hip_joint"/>
    <general name="fl_knee_act" joint="fl_knee_joint"/>
    <general name="fr_hip_act" joint="fr_hip_joint"/>
    <general name="fr_knee_act" joint="fr_knee_joint"/>
    <general name="spine_act" joint="spine_joint"/>
    <general name="bl_hip_act" joint="bl_hip_joint"/>
    <general name="bl_knee_act" joint="bl_knee_joint"/>
    <general name="br_hip_act" joint="br_hip_joint"/>
    <general name="br_knee_act" joint="br_knee_joint"/>
  </actuator>

  <sensor>
    <jointpos joint="fl_hip_joint" name="fl_hip_pos"/>
    <jointpos joint="fl_knee_joint" name="fl_knee_pos"/>
    <jointpos joint="fr_hip_joint" name="fr_hip_pos"/>
    <jointpos joint="fr_knee_joint" name="fr_knee_pos"/>
    <jointpos joint="spine_joint" name="spine_pos"/>
    <jointpos joint="bl_hip_joint" name="bl_hip_pos"/>
    <jointpos joint="bl_knee_joint" name="bl_knee_pos"/>
    <jointpos joint="br_hip_joint" name="br_hip_pos"/>
    <jointpos joint="br_knee_joint" name="br_knee_pos"/>
    <jointvel joint="fl_hip_joint" name="fl_hip_vel"/>
    <jointvel joint="fl_knee_joint" name="fl_knee_vel"/>
    <jointvel joint="fr_hip_joint" name="fr_hip_vel"/>
    <jointvel joint="fr_knee_joint" name="fr_knee_vel"/>
    <jointvel joint="spine_joint" name="spine_vel"/>
    <jointvel joint="bl_hip_joint" name="bl_hip_vel"/>
    <jointvel joint="bl_knee_joint" name="bl_knee_vel"/>
    <jointvel joint="br_hip_joint" name="br_hip_vel"/>
    <jointvel joint="br_knee_joint" name="br_knee_vel"/>
    <gyro site="imu_frame" name="gyro"/>
    <velocimeter site="imu_frame" name="local_linvel"/>
    <accelerometer site="imu_frame" name="accelerometer"/>
    <framepos objtype="site" objname="imu_frame" name="global_position"/>
    <framezaxis objtype="site" objname="imu_frame" name="upvector"/>
    <framelinvel objtype="site" objname="imu_frame" name="global_linvel"/>
    <frameangvel objtype="site" objname="imu_frame" name="global_angvel"/>
    <framequat objtype="site" objname="imu_frame" name="orientation"/>
  </sensor>

  <keyframe>
    <key name="home"
      qpos="0 0 0.39
            1 0 0 0
            0 0 
            0 0 
            -0.52 
            0 -0.1 
            0 -0.1"
      ctrl="0.15 0.3
            0.15 0.3
            -0.8
            0.1 -0.2
            0.1 -0.2"/>
  </keyframe>
</mujoco>
